const { expect } = require("chai");

const assert = {
    fail: function fail(message) {
        throw new Error(message);
    }
};

function verifyIsValidAssertion(assertionMethod, assertionArgs) {
    switch (assertionMethod) {
        case "notCalled":
        case "called":
        case "calledOnce":
        case "calledTwice":
        case "calledThrice":
            if (assertionArgs.length !== 0) {
                assert.fail(
                    `${assertionMethod} takes 1 argument but was called with ${assertionArgs.length + 1} arguments`
                );
            }
            break;
        default:
            break;
    }
}

describe("verifyIsValidAssertion", function () {
    it("should throw an error if assertion method is not called with correct number of arguments", function () {
        expect(() => verifyIsValidAssertion("notCalled", [1])).to.throw(
            Error,
            "notCalled takes 1 argument but was called with 2 arguments"
        );
        expect(() => verifyIsValidAssertion("called", [1, 2])).to.throw(
            Error,
            "called takes 1 argument but was called with 3 arguments"
        );
    });

    it("should not throw an error if assertion method is called with correct number of arguments", function () {
        expect(() => verifyIsValidAssertion("notCalled", [])).to.not.throw();
        expect(() => verifyIsValidAssertion("called", [])).to.not.throw();
        expect(() => verifyIsValidAssertion("calledOnce", [])).to.not.throw();
        expect(() => verifyIsValidAssertion("calledTwice", [])).to.not.throw();
        expect(() => verifyIsValidAssertion("calledThrice", [])).to.not.throw();
    });

    it("should not throw an error for unknown assertion method", function () {
        expect(() => verifyIsValidAssertion("unknownMethod", [])).to.not.throw();
    });
});
Running the Tests
├── test/
│   └── verifyIsValidAssertionTest.js
└── package.json
The output----------------------
    ✓ should throw an error if assertion method is not called with correct number of arguments
    ✓ should not throw an error if assertion method is called with correct number of arguments
    ✓ should not throw an error for unknown assertion method

  3 passing (XXms)

